Workbook

Sheet INTRODUCCION
B1: PROCESO
B2: 1. VAMOS A CALCULAR LA LEY BENFORD CON UNO, DOS Y LOS DOS PRIMEROS DIGITOS
B3: 2. LUEGO VAMOS A CALCULAR LA DESVIACION ABSOLUTA MEDIA
B4: 3. VAMOS A CALCULAR EL CHI CUADRADO Y LO VAMOS A COMPARAR CON EL VALOR DEL CHI CUADRADO CRITICO
B5: DE ACUERDO AL RESULTADO VAMOS A INDICAR SI LOS DATOS SON FIABLES O NO
B7: EN LAS SIGUIENTES HOJAS ESTAN LOS EJEMPLO DE CADA UNO DE ESTOS CASOS
B9: TODO PARTE DE UN MOVIMIENTO CONTABLE REAL QUE ESTA EN LA HOJA MOVIMIENTO
B11: VAMOS A HACER ESTA PRUEBA CON EL DATO VALOR QUE ESTA EN LA COLUMNA J
B13: TAMBIEN ES IMPORTANTE VER QUE TENEMOS 9.656 REGISTROS
B15: TENGAMOS EN CUENTA QUE CUANDO EL VALOR ES CERO
B16: PARA EL PRIMER, SEGUNDO Y DOS PRIMEROS VALORES TOME 0
B17: TAMBIEN CUANDO ES SOLO DE UN DIGITO, POR EJEMPLO 1 , ENTONCES PARA EL SEGUNDO VALOR Y LOS DOS PRIMEROS TOME 0

Sheet MOVIMIENTO
A1: REGISTRO | B1: CUENTA | C1: COMPROBANTE | D1: FECHA | E1: DOCUMENTO | F1: DOCUMENTO_REFERENCIA | G1: NIT | H1: DETALLE | I1: TIPO | J1: VALOR | K1: VALOR_BASE | L1: CENTRO_DE_COSTOS | M1: TRANSACCIÓN_BANCO | N1: PLAZO
A2: 1 | B2: 11050503 | C2: 23 | D2: 42736 | E2: 1 | F2: 1 | H2: CUADRE DE ITAG?? | I2: 2 | J2: 153800 | K2: 0 | N2: 0
A3: =+A2+1 -> 2 | B3: 28109500 | C3: 23 | D3: 42736 | E3: 1 | F3: 1 | G3: 1 | H3: CUADRE DE ITAG?? | I3: 2 | J3: 9000 | K3: 0 | N3: 0
A4: =+A3+1 -> 3 | B4: 11100502 | C4: 23 | D4: 42736 | E4: 1 | F4: 8521 | H4: CUADRE DE ITAG?? | I4: 1 | J4: 37800 | K4: 0 | N4: 0
A5: =+A4+1 -> 4 | B5: 11100504 | C5: 23 | D5: 42736 | E5: 1 | F5: 1 | H5: CUADRE DE ITAG?? | I5: 1 | J5: 100000 | K5: 0 | N5: 0
A6: =+A5+1 -> 5 | B6: 52359520 | C6: 23 | D6: 42736 | E6: 1 | F6: 2935 | G6: 71336216 | H6: CUADRE DE ITAG?? | I6: 1 | J6: 25000 | K6: 0 | L6: 4 | N6: 0
A7: =+A6+1 -> 6 | B7: 11050503 | C7: 23 | D7: 42767 | E7: 1 | F7: 1 | H7: CUADRE DE ITAG?? | I7: 2 | J7: 182900 | K7: 0 | N7: 0
A8: =+A7+1 -> 7 | B8: 11100502 | C8: 23 | D8: 42767 | E8: 1 | F8: 8522 | H8: CUADRE DE ITAG?? | I8: 1 | J8: 157900 | K8: 0 | N8: 0
A9: =+A8+1 -> 8 | B9: 52359510 | C9: 23 | D9: 42767 | E9: 1 | F9: 2936 | G9: 71336216 | H9: CUADRE DE ITAG?? | I9: 1 | J9: 25000 | K9: 0 | L9: 4 | N9: 0
A10: =+A9+1 -> 9 | B10: 11050503 | C10: 23 | D10: 42795 | E10: 1 | F10: 1 | H10: CUADRE DE ITAG?? | I10: 2 | J10: 181550 | K10: 0 | N10: 0
A11: =+A10+1 -> 10 | B11: 529530 | C11: 23 | D11: 42795 | E11: 1 | F11: 1 | G11: 70517854 | H11: CUADRE DE ITAG?? | I11: 1 | J11: 6000 | K11: 0 | L11: 4 | N11: 0
A12: =+A11+1 -> 11 | B12: 23354000 | C12: 23 | D12: 42795 | E12: 1 | F12: 1 | G12: 6788222 | H12: CUADRE DE ITAG?? | I12: 1 | J12: 175550 | K12: 0 | N12: 0
A13: =+A12+1 -> 12 | B13: 11050503 | C13: 23 | D13: 42826 | E13: 1 | F13: 1 | H13: CUADRE DE ITAG?? | I13: 2 | J13: 75500 | K13: 0 | N13: 0
A14: =+A13+1 -> 13 | B14: 73959510 | C14: 23 | D14: 42826 | E14: 1 | F14: 1 | G14: 19336633 | H14: CUADRE DE ITAG?? | I14: 1 | J14: 1000 | K14: 0 | L14: 4 | N14: 0
A15: =+A14+1 -> 14 | B15: 23354000 | C15: 23 | D15: 42826 | E15: 1 | F15: 1 | G15: 6788222 | H15: CUADRE DE ITAG?? | I15: 1 | J15: 74500 | K15: 0 | N15: 0
A16: =+A15+1 -> 15 | B16: 11050503 | C16: 23 | D16: 42856 | E16: 1 | F16: 1 | H16: CUADRE DE ITAG?? | I16: 2 | J16: 184610 | K16: 0 | N16: 0
A17: =+A16+1 -> 16 | B17: 23354000 | C17: 23 | D17: 42856 | E17: 1 | F17: 1 | G17: 6788222 | H17: CUADRE DE ITAG?? | I17: 1 | J17: 184610 | K17: 0 | N17: 0
A18: =+A17+1 -> 17 | B18: 11050503 | C18: 23 | D18: 42887 | E18: 1 | F18: 1 | H18: CUADRE DE ITAG?? | I18: 2 | J18: 128000 | K18: 0 | N18: 0
A19: =+A18+1 -> 18 | B19: 23354000 | C19: 23 | D19: 42887 | E19: 1 | F19: 1 | G19: 6788222 | H19: CUADRE DE ITAG?? | I19: 1 | J19: 128000 | K19: 0 | N19: 0
A20: =+A19+1 -> 19 | B20: 11050503 | C20: 23 | D20: 42917 | E20: 1 | F20: 1 | H20: CUADRE DE ITAG?? | I20: 2 | J20: 370370 | K20: 0 | N20: 0
A21: =+A20+1 -> 20 | B21: 23354000 | C21: 23 | D21: 42917 | E21: 1 | F21: 1 | G21: 6788222 | H21: CUADRE DE ITAG?? | I21: 1 | J21: 324485 | K21: 0 | N21: 0
A22: =+A21+1 -> 21 | B22: 11100502 | C22: 23 | D22: 42917 | E22: 1 | F22: 8560 | H22: CUADRE DE ITAG?? | I22: 1 | J22: 45885 | K22: 0 | N22: 0
A23: =+A22+1 -> 22 | B23: 11050503 | C23: 23 | D23: 42948 | E23: 1 | F23: 1 | H23: CUADRE DE ITAG?? | I23: 2 | J23: 352295 | K23: 0 | N23: 0
A24: =+A23+1 -> 23 | B24: 11100507 | C24: 23 | D24: 42948 | E24: 1 | F24: 2581 | H24: CUADRE DE ITAG?? | I24: 1 | J24: 335095 | K24: 0 | N24: 0
A25: =+A24+1 -> 24 | B25: 73959510 | C25: 23 | D25: 42948 | E25: 1 | F25: 2938 | G25: 21397122 | H25: CUADRE DE ITAG?? | I25: 1 | J25: 1800 | K25: 0 | L25: 4 | N25: 0
A26: =+A25+1 -> 25 | B26: 523505 | C26: 23 | D26: 42948 | E26: 1 | F26: 2937 | G26: 70516226 | H26: CUADRE DE ITAG?? | I26: 1 | J26: 7000 | K26: 0 | L26: 4 | N26: 0
A27: =+A26+1 -> 26 | B27: 22059510 | C27: 23 | D27: 42948 | E27: 1 | F27: 12757 | G27: 860025900 | H27: CUADRE DE ITAG?? | I27: 1 | J27: 8375 | K27: 0 | N27: 0
A28: =+A27+1 -> 27 | B28: 53955300 | C28: 23 | D28: 42948 | E28: 1 | F28: 1 | G28: 3399878 | H28: CUADRE DE ITAG?? | I28: 1 | J28: 25 | K28: 0 | L28: 4 | N28: 0
A29: =+A28+1 -> 28 | B29: 11050503 | C29: 23 | D29: 42979 | E29: 1 | F29: 1 | H29: CUADRE DE ITAG?? | I29: 2 | J29: 182350 | K29: 0 | N29: 0
A30: =+A29+1 -> 29 | B30: 11100507 | C30: 23 | D30: 42979 | E30: 1 | F30: 2578 | H30: CUADRE DE ITAG?? | I30: 1 | J30: 157350 | K30: 0 | N30: 0
A31: =+A30+1 -> 30 | B31: 52359520 | C31: 23 | D31: 42979 | E31: 1 | F31: 2939 | G31: 71336216 | H31: CUADRE DE ITAG?? | I31: 1 | J31: 25000 | K31: 0 | L31: 4 | N31: 0
A32: =+A31+1 -> 31 | B32: 11050503 | C32: 23 | D32: 43009 | E32: 1 | F32: 1 | H32: CUADRE DE ITAG?? | I32: 2 | J32: 126600 | K32: 0 | N32: 0
A33: =+A32+1 -> 32 | B33: 11100507 | C33: 23 | D33: 43009 | E33: 1 | F33: 2579 | H33: CUADRE DE ITAG?? | I33: 1 | J33: 101600 | K33: 0 | N33: 0
A34: =+A33+1 -> 33 | B34: 52359520 | C34: 23 | D34: 43009 | E34: 1 | F34: 2940 | G34: 71336216 | H34: CUADRE DE ITAG?? | I34: 1 | J34: 25000 | K34: 0 | L34: 4 | N34: 0
A35: =+A34+1 -> 34 | B35: 11050504 | C35: 27 | D35: 42736 | E35: 1 | F35: 1 | H35: CUADRE COPACABANA | I35: 2 | J35: 153300 | K35: 0 | N35: 0
A36: =+A35+1 -> 35 | B36: 11100504 | C36: 27 | D36: 42736 | E36: 1 | F36: 1 | H36: CUADRE COPACABANA | I36: 1 | J36: 153300 | K36: 0 | N36: 0
A37: =+A36+1 -> 36 | B37: 11050504 | C37: 27 | D37: 42767 | E37: 1 | F37: 1 | H37: CUADRE COPACABANA | I37: 2 | J37: 217300 | K37: 0 | N37: 0
A38: =+A37+1 -> 37 | B38: 11100502 | C38: 27 | D38: 42767 | E38: 1 | F38: 8514 | H38: CUADRE COPACABANA | I38: 1 | J38: 217300 | K38: 0 | N38: 0
A39: =+A38+1 -> 38 | B39: 11050504 | C39: 27 | D39: 42795 | E39: 1 | F39: 1 | H39: CUADRE COPACABANA | I39: 2 | J39: 152200 | K39: 0 | N39: 0
A40: =+A39+1 -> 39 | B40: 11100507 | C40: 27 | D40: 42795 | E40: 1 | F40: 2576 | H40: CUADRE COPACABANA | I40: 1 | J40: 147900 | K40: 0 | N40: 0
...

Sheet Hoja9
A1: 7841 | B1: 1 | C1: f | D1: 14301000 | E1: 1 | F1: 42760 | G1: 51779 | H1: 51779 | J1: Valor Inv. Docto 000051779 | K1: 2 | L1: 528193 | M1: 0 | P1: 0 | Y1: 1 | Z1: 1 | AA1: 1 | AB1: 1 | AC1: 43511.928 | AD1: 43511.928
A2: 7842 | B2: 1 | C2: f | D2: 24080120 | E2: 1 | F2: 42760 | G2: 51779 | H2: 51779 | I2: 39636059 | J2: Valor I.V.A Docto 000051779 | K2: 2 | L2: 19339 | M2: 193395 | P2: 0 | Y2: 1 | Z2: 1 | AA2: 1 | AB2: 1 | AC2: 43511.928 | AD2: 43511.928
A3: 7843 | B3: 1 | C3: f | D3: 41200907 | E3: 1 | F3: 42760 | G3: 51779 | H3: 51779 | I3: 39636059 | J3: VENTAS CREDITO FABRICA | K3: 2 | L3: 193395 | M3: 0 | N3: 1 | P3: 0 | Y3: 1 | Z3: 1 | AA3: 1 | AB3: 1 | AC3: 43511.928 | AD3: 43511.928
A4: 7844 | B4: 1 | C4: f | D4: 61200900 | E4: 1 | F4: 42760 | G4: 51779 | H4: 51779 | J4: Valor Costo Docto 000051779 | K4: 1 | L4: 528193 | M4: 0 | P4: 0 | Y4: 1 | Z4: 1 | AA4: 1 | AB4: 1 | AC4: 43511.928 | AD4: 43511.928
A5: 7845 | B5: 1 | C5: f | D5: 13050510 | E5: 1 | F5: 42760 | G5: 51780 | H5: 51780 | I5: 30238105 | J5: VLR TOTAL DOC 000051780 | K5: 1 | L5: 60999 | M5: 0 | P5: 0 | Y5: 1 | Z5: 1 | AA5: 1 | AB5: 1 | AC5: 43511.928 | AD5: 43511.928
A6: 7846 | B6: 1 | C6: f | D6: 14301000 | E6: 1 | F6: 42760 | G6: 51780 | H6: 51780 | J6: Valor Inv. Docto 000051780 | K6: 2 | L6: 64873 | M6: 0 | P6: 0 | Y6: 1 | Z6: 1 | AA6: 1 | AB6: 1 | AC6: 43511.928 | AD6: 43511.928
A7: 7847 | B7: 1 | C7: f | D7: 24080120 | E7: 1 | F7: 42760 | G7: 51780 | H7: 51780 | I7: 30238105 | J7: Valor I.V.A Docto 000051780 | K7: 2 | L7: 5545 | M7: 55454 | P7: 0 | Y7: 1 | Z7: 1 | AA7: 1 | AB7: 1 | AC7: 43511.928 | AD7: 43511.928
A8: 7848 | B8: 1 | C8: f | D8: 41200907 | E8: 1 | F8: 42760 | G8: 51780 | H8: 51780 | I8: 30238105 | J8: VENTAS CREDITO FABRICA | K8: 2 | L8: 55454 | M8: 0 | N8: 1 | P8: 0 | Y8: 1 | Z8: 1 | AA8: 1 | AB8: 1 | AC8: 43511.928 | AD8: 43511.928
A9: 7849 | B9: 1 | C9: f | D9: 61200900 | E9: 1 | F9: 42760 | G9: 51780 | H9: 51780 | J9: Valor Costo Docto 000051780 | K9: 1 | L9: 64873 | M9: 0 | P9: 0 | Y9: 1 | Z9: 1 | AA9: 1 | AB9: 1 | AC9: 43511.928 | AD9: 43511.928
A10: 7850 | B10: 1 | C10: f | D10: 13050510 | E10: 1 | F10: 42760 | G10: 51781 | H10: 51781 | I10: 7422201 | J10: VLR TOTAL DOC 000051781 | K10: 1 | L10: 295522 | M10: 0 | P10: 15 | Y10: 1 | Z10: 1 | AA10: 1 | AB10: 1 | AC10: 43511.928 | AD10: 43511.928
A11: 7851 | B11: 1 | C11: f | D11: 14301000 | E11: 1 | F11: 42760 | G11: 51781 | H11: 51781 | J11: Valor Inv. Docto 000051781 | K11: 2 | L11: 648712 | M11: 0 | P11: 15 | Y11: 1 | Z11: 1 | AA11: 1 | AB11: 1 | AC11: 43511.928 | AD11: 43511.928
A12: 7852 | B12: 1 | C12: f | D12: 24080120 | E12: 1 | F12: 42760 | G12: 51781 | H12: 51781 | I12: 7422201 | J12: Valor I.V.A Docto 000051781 | K12: 2 | L12: 26866 | M12: 268656 | P12: 15 | Y12: 1 | Z12: 1 | AA12: 1 | AB12: 1 | AC12: 43511.928 | AD12: 43511.928
A13: 7853 | B13: 1 | C13: f | D13: 41200907 | E13: 1 | F13: 42760 | G13: 51781 | H13: 51781 | I13: 7422201 | J13: VENTAS CREDITO FABRICA | K13: 2 | L13: 268656 | M13: 0 | N13: 1 | P13: 15 | Y13: 1 | Z13: 1 | AA13: 1 | AB13: 1 | AC13: 43511.928 | AD13: 43511.928
A14: 7854 | B14: 1 | C14: f | D14: 61200900 | E14: 1 | F14: 42760 | G14: 51781 | H14: 51781 | J14: Valor Costo Docto 000051781 | K14: 1 | L14: 648712 | M14: 0 | P14: 15 | Y14: 1 | Z14: 1 | AA14: 1 | AB14: 1 | AC14: 43511.928 | AD14: 43511.928
A15: 7855 | B15: 1 | C15: f | D15: 13050510 | E15: 1 | F15: 42760 | G15: 51782 | H15: 51782 | I15: 10273897 | J15: VLR TOTAL DOC 000051782 | K15: 1 | L15: 544161 | M15: 0 | P15: 8 | Y15: 1 | Z15: 1 | AA15: 1 | AB15: 1 | AC15: 43511.928 | AD15: 43511.928
A16: 7856 | B16: 1 | C16: f | D16: 14301000 | E16: 1 | F16: 42760 | G16: 51782 | H16: 51782 | J16: Valor Inv. Docto 000051782 | K16: 2 | L16: 435328 | M16: 0 | P16: 0 | Y16: 1 | Z16: 1 | AA16: 1 | AB16: 1 | AC16: 43511.928 | AD16: 43511.928
A17: 7857 | B17: 1 | C17: f | D17: 24080120 | E17: 1 | F17: 42760 | G17: 51782 | H17: 51782 | I17: 10273897 | J17: Valor I.V.A Docto 000051782 | K17: 2 | L17: 49469 | M17: 494692 | P17: 8 | Y17: 1 | Z17: 1 | AA17: 1 | AB17: 1 | AC17: 43511.928 | AD17: 43511.928
A18: 7858 | B18: 1 | C18: f | D18: 41200907 | E18: 1 | F18: 42760 | G18: 51782 | H18: 51782 | I18: 10273897 | J18: VENTAS CREDITO FABRICA | K18: 2 | L18: 494692 | M18: 0 | N18: 1 | P18: 8 | Y18: 1 | Z18: 1 | AA18: 1 | AB18: 1 | AC18: 43511.928 | AD18: 43511.928
A19: 7859 | B19: 1 | C19: f | D19: 61200900 | E19: 1 | F19: 42760 | G19: 51782 | H19: 51782 | J19: Valor Costo Docto 000051782 | K19: 1 | L19: 435328 | M19: 0 | P19: 0 | Y19: 1 | Z19: 1 | AA19: 1 | AB19: 1 | AC19: 43511.928 | AD19: 43511.928
A20: 7860 | B20: 1 | C20: f | D20: 13050510 | E20: 1 | F20: 42760 | G20: 51783 | H20: 51783 | I20: 1 | J20: VLR TOTAL DOC 000051783 | K20: 1 | L20: 12350 | M20: 0 | P20: 0 | Y20: 1 | Z20: 1 | AA20: 1 | AB20: 1 | AC20: 43511.928 | AD20: 43511.928
A21: 7861 | B21: 1 | C21: f | D21: 14301000 | E21: 1 | F21: 42760 | G21: 51783 | H21: 51783 | J21: Valor Inv. Docto 000051783 | K21: 2 | L21: 11321 | M21: 0 | P21: 0 | Y21: 1 | Z21: 1 | AA21: 1 | AB21: 1 | AC21: 43511.928 | AD21: 43511.928
A22: 7862 | B22: 1 | C22: f | D22: 24080120 | E22: 1 | F22: 42760 | G22: 51783 | H22: 51783 | I22: 1 | J22: Valor I.V.A Docto 000051783 | K22: 2 | L22: 1123 | M22: 11227 | P22: 0 | Y22: 1 | Z22: 1 | AA22: 1 | AB22: 1 | AC22: 43511.928 | AD22: 43511.928
A23: 7863 | B23: 1 | C23: f | D23: 41200907 | E23: 1 | F23: 42760 | G23: 51783 | H23: 51783 | I23: 1 | J23: VENTAS CREDITO FABRICA | K23: 2 | L23: 11227 | M23: 0 | N23: 1 | P23: 0 | Y23: 1 | Z23: 1 | AA23: 1 | AB23: 1 | AC23: 43511.928 | AD23: 43511.928
A24: 7864 | B24: 1 | C24: f | D24: 61200900 | E24: 1 | F24: 42760 | G24: 51783 | H24: 51783 | J24: Valor Costo Docto 000051783 | K24: 1 | L24: 11321 | M24: 0 | P24: 0 | Y24: 1 | Z24: 1 | AA24: 1 | AB24: 1 | AC24: 43511.928 | AD24: 43511.928
A25: 7865 | B25: 1 | C25: f | D25: 13050510 | E25: 1 | F25: 42760 | G25: 51784 | H25: 51784 | I25: 66963257 | J25: VLR TOTAL DOC 000051784 | K25: 1 | L25: 80791 | M25: 0 | P25: 0 | Y25: 1 | Z25: 1 | AA25: 1 | AB25: 1 | AC25: 43511.928 | AD25: 43511.928
A26: 7866 | B26: 1 | C26: f | D26: 14301000 | E26: 1 | F26: 42760 | G26: 51784 | H26: 51784 | J26: Valor Inv. Docto 000051784 | K26: 2 | L26: 135203 | M26: 0 | P26: 0 | Y26: 1 | Z26: 1 | AA26: 1 | AB26: 1 | AC26: 43511.928 | AD26: 43511.928
A27: 7867 | B27: 1 | C27: f | D27: 24080120 | E27: 1 | F27: 42760 | G27: 51784 | H27: 51784 | I27: 66963257 | J27: Valor I.V.A Docto 000051784 | K27: 2 | L27: 7345 | M27: 73446 | P27: 0 | Y27: 1 | Z27: 1 | AA27: 1 | AB27: 1 | AC27: 43511.928 | AD27: 43511.928
A28: 7868 | B28: 1 | C28: f | D28: 41200907 | E28: 1 | F28: 42760 | G28: 51784 | H28: 51784 | I28: 66963257 | J28: VENTAS CREDITO FABRICA | K28: 2 | L28: 73446 | M28: 0 | N28: 1 | P28: 0 | Y28: 1 | Z28: 1 | AA28: 1 | AB28: 1 | AC28: 43511.928 | AD28: 43511.928
A29: 7869 | B29: 1 | C29: f | D29: 61200900 | E29: 1 | F29: 42760 | G29: 51784 | H29: 51784 | J29: Valor Costo Docto 000051784 | K29: 1 | L29: 135203 | M29: 0 | P29: 0 | Y29: 1 | Z29: 1 | AA29: 1 | AB29: 1 | AC29: 43511.928 | AD29: 43511.928
A30: 7870 | B30: 1 | C30: f | D30: 13050510 | E30: 1 | F30: 42760 | G30: 51785 | H30: 51785 | I30: 71718340 | J30: VLR TOTAL DOC 000051785 | K30: 1 | L30: 71975 | M30: 0 | P30: 8 | Y30: 1 | Z30: 1 | AA30: 1 | AB30: 1 | AC30: 43511.928 | AD30: 43511.928
A31: 7871 | B31: 1 | C31: f | D31: 14301000 | E31: 1 | F31: 42760 | G31: 51785 | H31: 51785 | J31: Valor Inv. Docto 000051785 | K31: 2 | L31: 119573 | M31: 0 | P31: 8 | Y31: 1 | Z31: 1 | AA31: 1 | AB31: 1 | AC31: 43511.928 | AD31: 43511.928
A32: 7872 | B32: 1 | C32: f | D32: 24080120 | E32: 1 | F32: 42760 | G32: 51785 | H32: 51785 | I32: 71718340 | J32: Valor I.V.A Docto 000051785 | K32: 2 | L32: 6543 | M32: 65432 | P32: 8 | Y32: 1 | Z32: 1 | AA32: 1 | AB32: 1 | AC32: 43511.928 | AD32: 43511.928
A33: 7873 | B33: 1 | C33: f | D33: 41200907 | E33: 1 | F33: 42760 | G33: 51785 | H33: 51785 | I33: 71718340 | J33: VENTAS CREDITO FABRICA | K33: 2 | L33: 65432 | M33: 0 | N33: 1 | P33: 8 | Y33: 1 | Z33: 1 | AA33: 1 | AB33: 1 | AC33: 43511.928 | AD33: 43511.928
A34: 7874 | B34: 1 | C34: f | D34: 61200900 | E34: 1 | F34: 42760 | G34: 51785 | H34: 51785 | J34: Valor Costo Docto 000051785 | K34: 1 | L34: 119573 | M34: 0 | P34: 8 | Y34: 1 | Z34: 1 | AA34: 1 | AB34: 1 | AC34: 43511.928 | AD34: 43511.928
A35: 7875 | B35: 1 | C35: f | D35: 13050510 | E35: 1 | F35: 42760 | G35: 51786 | H35: 51786 | I35: 42763194 | J35: VLR TOTAL DOC 000051786 | K35: 1 | L35: 26270 | M35: 0 | P35: 0 | Y35: 1 | Z35: 1 | AA35: 1 | AB35: 1 | AC35: 43511.928 | AD35: 43511.928
A36: 7876 | B36: 1 | C36: f | D36: 14301000 | E36: 1 | F36: 42760 | G36: 51786 | H36: 51786 | J36: Valor Inv. Docto 000051786 | K36: 2 | L36: 75009 | M36: 0 | P36: 0 | Y36: 1 | Z36: 1 | AA36: 1 | AB36: 1 | AC36: 43511.928 | AD36: 43511.928
A37: 7877 | B37: 1 | C37: f | D37: 24080120 | E37: 1 | F37: 42760 | G37: 51786 | H37: 51786 | I37: 42763194 | J37: Valor I.V.A Docto 000051786 | K37: 2 | L37: 2388 | M37: 23882 | P37: 0 | Y37: 1 | Z37: 1 | AA37: 1 | AB37: 1 | AC37: 43511.928 | AD37: 43511.928
A38: 7878 | B38: 1 | C38: f | D38: 41200907 | E38: 1 | F38: 42760 | G38: 51786 | H38: 51786 | I38: 42763194 | J38: VENTAS CREDITO FABRICA | K38: 2 | L38: 23882 | M38: 0 | N38: 1 | P38: 0 | Y38: 1 | Z38: 1 | AA38: 1 | AB38: 1 | AC38: 43511.928 | AD38: 43511.928
A39: 7879 | B39: 1 | C39: f | D39: 61200900 | E39: 1 | F39: 42760 | G39: 51786 | H39: 51786 | J39: Valor Costo Docto 000051786 | K39: 1 | L39: 75009 | M39: 0 | P39: 0 | Y39: 1 | Z39: 1 | AA39: 1 | AB39: 1 | AC39: 43511.928 | AD39: 43511.928
A40: 7880 | B40: 1 | C40: f | D40: 13050510 | E40: 1 | F40: 42760 | G40: 51787 | H40: 51787 | I40: 1 | J40: VLR TOTAL DOC 000051787 | K40: 1 | L40: 4421 | M40: 0 | P40: 0 | Y40: 1 | Z40: 1 | AA40: 1 | AB40: 1 | AC40: 43511.928 | AD40: 43511.928
...

Sheet PRIMER DIGITO
A1: REGISTRO | B1: VALOR | C1: VAMOS A EXTRAER EL PRIMER DIGITO | J1: DESVIACION ABSOLUTA MEDIA (MAD)
A2: 1 | B2: 153800 | C2: =_xlfn.NUMBERVALUE(MID(B2,1,1)) -> 1 | I2: VALOR ABSOLUTO (FRECUENCIA OBSERVADA - FRECUENCIA ESPERADA)
A3: =+A2+1 -> 2 | B3: 9000 | C3: =_xlfn.NUMBERVALUE(MID(B3,1,1)) -> 9 | D3: VAMOS A VER LA FRECUENCIA EN QUE SE REPITE CADA NUMERO | I3: N = 9
A4: =+A3+1 -> 3 | B4: 37800 | C4: =_xlfn.NUMBERVALUE(MID(B4,1,1)) -> 3 | E4: ACUMULADA | F4: FRECUENCIA | G4: % OBSERVADO | H4: BENFORD PRIMER DIGITO | J4: VARIACION | K4: VALOR ABSOLUTO
A5: =+A4+1 -> 4 | B5: 100000 | C5: =_xlfn.NUMBERVALUE(MID(B5,1,1)) -> 1 | D5: 1 | E5: =FREQUENCY($C$2:$C$9657,D5) -> 3317 | F5: =+E5 -> 3317 | G5: =+F5/$F$15 -> 0.34351698 | H5: 0.30103 | J5: =+(G5-H5) -> 0.042486989 | K5: =ABS(J5) -> 0.042486989
A6: =+A5+1 -> 5 | B6: 25000 | C6: =_xlfn.NUMBERVALUE(MID(B6,1,1)) -> 2 | D6: 2 | E6: =FREQUENCY($C$2:$C$9657,D6) -> 5069 | F6: =+E6-E5 -> 1752 | G6: =+F6/$F$15 -> 0.18144159 | H6: 0.17609126 | J6: =+(G6-H6) -> 0.0053503317 | K6: =ABS(J6) -> 0.0053503317
A7: =+A6+1 -> 6 | B7: 182900 | C7: =_xlfn.NUMBERVALUE(MID(B7,1,1)) -> 1 | D7: 3 | E7: =FREQUENCY($C$2:$C$9657,D7) -> 6240 | F7: =+E7-E6 -> 1171 | G7: =+F7/$F$15 -> 0.12127175 | H7: 0.12493874 | J7: =+(G7-H7) -> -0.0036669885 | K7: =ABS(J7) -> 0.0036669885
A8: =+A7+1 -> 7 | B8: 157900 | C8: =_xlfn.NUMBERVALUE(MID(B8,1,1)) -> 1 | D8: 4 | E8: =FREQUENCY($C$2:$C$9657,D8) -> 7061 | F8: =+E8-E7 -> 821 | G8: =+F8/$F$15 -> 0.085024855 | H8: 0.096910013 | J8: =+(G8-H8) -> -0.011885158 | K8: =ABS(J8) -> 0.011885158 | L8: MAD | M8: =+K15/9 -> 0.010630516
A9: =+A8+1 -> 8 | B9: 25000 | C9: =_xlfn.NUMBERVALUE(MID(B9,1,1)) -> 2 | D9: 5 | E9: =FREQUENCY($C$2:$C$9657,D9) -> 7790 | F9: =+E9-E8 -> 729 | G9: =+F9/$F$15 -> 0.0754971 | H9: 0.079181246 | J9: =+(G9-H9) -> -0.0036841458 | K9: =ABS(J9) -> 0.0036841458
A10: =+A9+1 -> 9 | B10: 181550 | C10: =_xlfn.NUMBERVALUE(MID(B10,1,1)) -> 1 | D10: 6 | E10: =FREQUENCY($C$2:$C$9657,D10) -> 8310 | F10: =+E10-E9 -> 520 | G10: =+F10/$F$15 -> 0.053852527 | H10: 0.06694679 | J10: =+(G10-H10) -> -0.013094263 | K10: =ABS(J10) -> 0.013094263
A11: =+A10+1 -> 10 | B11: 6000 | C11: =_xlfn.NUMBERVALUE(MID(B11,1,1)) -> 6 | D11: 7 | E11: =FREQUENCY($C$2:$C$9657,D11) -> 8808 | F11: =+E11-E10 -> 498 | G11: =+F11/$F$15 -> 0.051574151 | H11: 0.057991947 | J11: =+(G11-H11) -> -0.0064177962 | K11: =ABS(J11) -> 0.0064177962
A12: =+A11+1 -> 11 | B12: 175550 | C12: =_xlfn.NUMBERVALUE(MID(B12,1,1)) -> 1 | D12: 8 | E12: =FREQUENCY($C$2:$C$9657,D12) -> 9259 | F12: =+E12-E11 -> 451 | G12: =+F12/$F$15 -> 0.046706711 | H12: 0.051152522 | J12: =+(G12-H12) -> -0.0044458116 | K12: =ABS(J12) -> 0.0044458116
A13: =+A12+1 -> 12 | B13: 75500 | C13: =_xlfn.NUMBERVALUE(MID(B13,1,1)) -> 7 | D13: 9 | E13: =FREQUENCY($C$2:$C$9657,D13) -> 9656 | F13: =+E13-E12 -> 397 | G13: =+F13/$F$15 -> 0.041114333 | H13: 0.045757491 | J13: =+(G13-H13) -> -0.0046431575 | K13: =ABS(J13) -> 0.0046431575
A14: =+A13+1 -> 13 | B14: 1000 | C14: =_xlfn.NUMBERVALUE(MID(B14,1,1)) -> 1
A15: =+A14+1 -> 14 | B15: 74500 | C15: =_xlfn.NUMBERVALUE(MID(B15,1,1)) -> 7 | E15: TOTAL | F15: =SUM(F5:F14) -> 9656 | G15: =SUM(G5:G14) -> 1 | H15: =SUM(H5:H14) -> 1 | K15: =SUM(K5:K14) -> 0.095674641
A16: =+A15+1 -> 15 | B16: 184610 | C16: =_xlfn.NUMBERVALUE(MID(B16,1,1)) -> 1
A17: =+A16+1 -> 16 | B17: 184610 | C17: =_xlfn.NUMBERVALUE(MID(B17,1,1)) -> 1
A18: =+A17+1 -> 17 | B18: 128000 | C18: =_xlfn.NUMBERVALUE(MID(B18,1,1)) -> 1 | F18: ESTA MAD LA COMPARAMOS CON LA TABLA PARAEL PRIMER DIGITO
A19: =+A18+1 -> 18 | B19: 128000 | C19: =_xlfn.NUMBERVALUE(MID(B19,1,1)) -> 1
A20: =+A19+1 -> 19 | B20: 370370 | C20: =_xlfn.NUMBERVALUE(MID(B20,1,1)) -> 3
A21: =+A20+1 -> 20 | B21: 324485 | C21: =_xlfn.NUMBERVALUE(MID(B21,1,1)) -> 3
A22: =+A21+1 -> 21 | B22: 45885 | C22: =_xlfn.NUMBERVALUE(MID(B22,1,1)) -> 4
A23: =+A22+1 -> 22 | B23: 352295 | C23: =_xlfn.NUMBERVALUE(MID(B23,1,1)) -> 3
A24: =+A23+1 -> 23 | B24: 335095 | C24: =_xlfn.NUMBERVALUE(MID(B24,1,1)) -> 3
A25: =+A24+1 -> 24 | B25: 1800 | C25: =_xlfn.NUMBERVALUE(MID(B25,1,1)) -> 1
A26: =+A25+1 -> 25 | B26: 7000 | C26: =_xlfn.NUMBERVALUE(MID(B26,1,1)) -> 7 | E26: EN ESTE CASO NOS DA 0.01063052 QUE VIENDOLO EN LA TABA ES CONFORMIDAD ACEPTABLE
A27: =+A26+1 -> 26 | B27: 8375 | C27: =_xlfn.NUMBERVALUE(MID(B27,1,1)) -> 8
A28: =+A27+1 -> 27 | B28: 25 | C28: =_xlfn.NUMBERVALUE(MID(B28,1,1)) -> 2
A29: =+A28+1 -> 28 | B29: 182350 | C29: =_xlfn.NUMBERVALUE(MID(B29,1,1)) -> 1 | J29: CHI CUADRADO Y CHI CUADRADO CRITICO
A30: =+A29+1 -> 29 | B30: 157350 | C30: =_xlfn.NUMBERVALUE(MID(B30,1,1)) -> 1 | I30: SUMATORIA DE VALOR OBSERVADO MENOS VALOR ESPERADO ELEVADO AL CUADRADO
A31: =+A30+1 -> 30 | B31: 25000 | C31: =_xlfn.NUMBERVALUE(MID(B31,1,1)) -> 2 | I31: VALOR ESPERADO
A32: =+A31+1 -> 31 | B32: 126600 | C32: =_xlfn.NUMBERVALUE(MID(B32,1,1)) -> 1 | D32: VAMOS A VER LA FRECUENCIA EN QUE SE REPITE CADA NUMERO | J32: VALOR ESPERADO BENFORD = TOTAL DATOSPOR % BENFORD
B33: 101600 | C33: =_xlfn.NUMBERVALUE(MID(B33,1,1)) -> 1 | E33: ACUMULADA | F33: FRECUENCIA | G33: % OBSERVADO | H33: BENFORD UN DIGITO | K33: VALOR OBSERVADO MENOS VALOR ESPERADO ELEVADO AL CUADRADO
A34: =+A33+1 -> 1 | B34: 25000 | C34: =_xlfn.NUMBERVALUE(MID(B34,1,1)) -> 2 | D34: 1 | E34: =FREQUENCY($C$2:$C$9657,D34) -> 3317 | F34: =+E34 -> 3317 | G34: =+F34/$F$15 -> 0.34351698 | H34: 0.30103 | J34: =+$F$44*H34 -> 2906.7456 | K34: =+((F34-J34)^2)/J34 -> 57.902776
A35: =+A34+1 -> 2 | B35: 153300 | C35: =_xlfn.NUMBERVALUE(MID(B35,1,1)) -> 1 | D35: 2 | E35: =FREQUENCY($C$2:$C$9657,D35) -> 5069 | F35: =+E35-E34 -> 1752 | G35: =+F35/$F$15 -> 0.18144159 | H35: 0.17609126 | J35: =+$F$44*H35 -> 1700.3372 | K35: =+((F35-J35)^2)/J35 -> 1.5697152
A36: =+A35+1 -> 3 | B36: 153300 | C36: =_xlfn.NUMBERVALUE(MID(B36,1,1)) -> 1 | D36: 3 | E36: =FREQUENCY($C$2:$C$9657,D36) -> 6240 | F36: =+E36-E35 -> 1171 | G36: =+F36/$F$15 -> 0.12127175 | H36: 0.12493874 | J36: =+$F$44*H36 -> 1206.4084 | K36: =+((F36-J36)^2)/J36 -> 1.0392481
A37: =+A36+1 -> 4 | B37: 217300 | C37: =_xlfn.NUMBERVALUE(MID(B37,1,1)) -> 2 | D37: 4 | E37: =FREQUENCY($C$2:$C$9657,D37) -> 7061 | F37: =+E37-E36 -> 821 | G37: =+F37/$F$15 -> 0.085024855 | H37: 0.096910013 | J37: =+$F$44*H37 -> 935.76309 | K37: =+((F37-J37)^2)/J37 -> 14.07468
A38: =+A37+1 -> 5 | B38: 217300 | C38: =_xlfn.NUMBERVALUE(MID(B38,1,1)) -> 2 | D38: 5 | E38: =FREQUENCY($C$2:$C$9657,D38) -> 7790 | F38: =+E38-E37 -> 729 | G38: =+F38/$F$15 -> 0.0754971 | H38: 0.079181246 | J38: =+$F$44*H38 -> 764.57411 | K38: =+((F38-J38)^2)/J38 -> 1.6551926
A39: =+A38+1 -> 6 | B39: 152200 | C39: =_xlfn.NUMBERVALUE(MID(B39,1,1)) -> 1 | D39: 6 | E39: =FREQUENCY($C$2:$C$9657,D39) -> 8310 | F39: =+E39-E38 -> 520 | G39: =+F39/$F$15 -> 0.053852527 | H39: 0.06694679 | J39: =+$F$44*H39 -> 646.4382 | K39: =+((F39-J39)^2)/J39 -> 24.730312
A40: =+A39+1 -> 7 | B40: 147900 | C40: =_xlfn.NUMBERVALUE(MID(B40,1,1)) -> 1 | D40: 7 | E40: =FREQUENCY($C$2:$C$9657,D40) -> 8808 | F40: =+E40-E39 -> 498 | G40: =+F40/$F$15 -> 0.051574151 | H40: 0.057991947 | J40: =+$F$44*H40 -> 559.97024 | K40: =+((F40-J40)^2)/J40 -> 6.858062
...

Sheet SEGUNDO DIGITO
A1: REGISTRO | B1: VALOR | C1: VAMOS A EXTRAER EL SEGUNDO DIGITO | J1: DESVIACION ABSOLUTA MEDIA (MAD)
A2: 1 | B2: 153800 | C2: =_xlfn.NUMBERVALUE(MID(B2,2,1)) -> 5 | I2: VALOR ABSOLUTO (FRECUENCIA OBSERVADA - FRECUENCIA ESPERADA)
A3: 2 | B3: 9000 | C3: =_xlfn.NUMBERVALUE(MID(B3,2,1)) -> 0 | D3: VAMOS A VER LA FRECUENCIA EN QUE SE REPITE CADA NUMERO | I3: N = 10
A4: 3 | B4: 37800 | C4: =_xlfn.NUMBERVALUE(MID(B4,2,1)) -> 7 | E4: ACUMULADA | F4: FRECUENCIA | G4: % OBSERVADO | H4: BENFORD SEGUNDO DIGITO | J4: VARIACION | K4: VALOR ABSOLUTO
A5: 4 | B5: 100000 | C5: =_xlfn.NUMBERVALUE(MID(B5,2,1)) -> 0 | D5: 0 | E5: =FREQUENCY($C$2:$C$9657,D5) -> #VALUE! | F5: =+E5 -> #VALUE! | G5: =+F5/$F$16 -> #VALUE! | H5: 0.11967927 | J5: =+(G5-H5) -> #VALUE! | K5: =ABS(J5) -> #VALUE!
A6: 5 | B6: 25000 | C6: =_xlfn.NUMBERVALUE(MID(B6,2,1)) -> 5 | D6: 1 | E6: =FREQUENCY($C$2:$C$9657,D6) -> #VALUE! | F6: =+E6-F5 -> #VALUE! | G6: =+F6/$F$16 -> #VALUE! | H6: 0.1138901 | J6: =+(G6-H6) -> #VALUE! | K6: =ABS(J6) -> #VALUE!
A7: 6 | B7: 182900 | C7: =_xlfn.NUMBERVALUE(MID(B7,2,1)) -> 8 | D7: 2 | E7: =FREQUENCY($C$2:$C$9657,D7) -> #VALUE! | F7: =+E7-E6 -> #VALUE! | G7: =+F7/$F$16 -> #VALUE! | H7: 0.1088215 | J7: =+(G7-H7) -> #VALUE! | K7: =ABS(J7) -> #VALUE!
A8: 7 | B8: 157900 | C8: =_xlfn.NUMBERVALUE(MID(B8,2,1)) -> 5 | D8: 3 | E8: =FREQUENCY($C$2:$C$9657,D8) -> #VALUE! | F8: =+E8-E7 -> #VALUE! | G8: =+F8/$F$16 -> #VALUE! | H8: 0.10432956 | J8: =+(G8-H8) -> #VALUE! | K8: =ABS(J8) -> #VALUE!
A9: 8 | B9: 25000 | C9: =_xlfn.NUMBERVALUE(MID(B9,2,1)) -> 5 | D9: 4 | E9: =FREQUENCY($C$2:$C$9657,D9) -> #VALUE! | F9: =+E9-E8 -> #VALUE! | G9: =+F9/$F$16 -> #VALUE! | H9: 0.1003082 | J9: =+(G9-H9) -> #VALUE! | K9: =ABS(J9) -> #VALUE! | L9: MAD | M9: =+K16/10 -> #VALUE!
A10: 9 | B10: 181550 | C10: =_xlfn.NUMBERVALUE(MID(B10,2,1)) -> 8 | D10: 5 | E10: =FREQUENCY($C$2:$C$9657,D10) -> #VALUE! | F10: =+E10-E9 -> #VALUE! | G10: =+F10/$F$16 -> #VALUE! | H10: 0.096677236 | J10: =+(G10-H10) -> #VALUE! | K10: =ABS(J10) -> #VALUE!
A11: 10 | B11: 6000 | C11: =_xlfn.NUMBERVALUE(MID(B11,2,1)) -> 0 | D11: 6 | E11: =FREQUENCY($C$2:$C$9657,D11) -> #VALUE! | F11: =+E11-E10 -> #VALUE! | G11: =+F11/$F$16 -> #VALUE! | H11: 0.093374736 | J11: =+(G11-H11) -> #VALUE! | K11: =ABS(J11) -> #VALUE!
A12: 11 | B12: 175550 | C12: =_xlfn.NUMBERVALUE(MID(B12,2,1)) -> 7 | D12: 7 | E12: =FREQUENCY($C$2:$C$9657,D12) -> #VALUE! | F12: =+E12-E11 -> #VALUE! | G12: =+F12/$F$16 -> #VALUE! | H12: 0.090351989 | J12: =+(G12-H12) -> #VALUE! | K12: =ABS(J12) -> #VALUE!
A13: 12 | B13: 75500 | C13: =_xlfn.NUMBERVALUE(MID(B13,2,1)) -> 5 | D13: 8 | E13: =FREQUENCY($C$2:$C$9657,D13) -> #VALUE! | F13: =+E13-E12 -> #VALUE! | G13: =+F13/$F$16 -> #VALUE! | H13: 0.087570054 | J13: =+(G13-H13) -> #VALUE! | K13: =ABS(J13) -> #VALUE!
A14: 13 | B14: 1000 | C14: =_xlfn.NUMBERVALUE(MID(B14,2,1)) -> 0 | D14: 9 | E14: =FREQUENCY($C$2:$C$9657,D14) -> #VALUE! | F14: =+E14-E13 -> #VALUE! | G14: =+F14/$F$16 -> #VALUE! | H14: 0.084997352 | J14: =+(G14-H14) -> #VALUE! | K14: =ABS(J14) -> #VALUE!
A15: 14 | B15: 74500 | C15: =_xlfn.NUMBERVALUE(MID(B15,2,1)) -> 4
A16: 15 | B16: 184610 | C16: =_xlfn.NUMBERVALUE(MID(B16,2,1)) -> 8 | E16: TOTAL | F16: =SUM(F5:F15) -> #VALUE! | G16: =SUM(G5:G15) -> #VALUE! | H16: =SUM(H5:H14) -> 1 | K16: =SUM(K5:K15) -> #VALUE!
A17: 16 | B17: 184610 | C17: =_xlfn.NUMBERVALUE(MID(B17,2,1)) -> 8
A18: 17 | B18: 128000 | C18: =_xlfn.NUMBERVALUE(MID(B18,2,1)) -> 2
A19: 18 | B19: 128000 | C19: =_xlfn.NUMBERVALUE(MID(B19,2,1)) -> 2 | G19: ESTA MAD LA COMPARAMOS CON LA TABLA PARA EL SEGUNDO DIGITO
A20: 19 | B20: 370370 | C20: =_xlfn.NUMBERVALUE(MID(B20,2,1)) -> 7
A21: 20 | B21: 324485 | C21: =_xlfn.NUMBERVALUE(MID(B21,2,1)) -> 2
A22: 21 | B22: 45885 | C22: =_xlfn.NUMBERVALUE(MID(B22,2,1)) -> 5
A23: 22 | B23: 352295 | C23: =_xlfn.NUMBERVALUE(MID(B23,2,1)) -> 5
A24: 23 | B24: 335095 | C24: =_xlfn.NUMBERVALUE(MID(B24,2,1)) -> 3
A25: 24 | B25: 1800 | C25: =_xlfn.NUMBERVALUE(MID(B25,2,1)) -> 8
A26: 25 | B26: 7000 | C26: =_xlfn.NUMBERVALUE(MID(B26,2,1)) -> 0
A27: 26 | B27: 8375 | C27: =_xlfn.NUMBERVALUE(MID(B27,2,1)) -> 3 | E27: EN ESTE CASO NOS DA 0.00686873 QUE VIENDOLO EN LA TABA ES CONFORMIDAD CUASI- PERFECTA
A28: 27 | B28: 25 | C28: =_xlfn.NUMBERVALUE(MID(B28,2,1)) -> 5
A29: 28 | B29: 182350 | C29: =_xlfn.NUMBERVALUE(MID(B29,2,1)) -> 8
A30: 29 | B30: 157350 | C30: =_xlfn.NUMBERVALUE(MID(B30,2,1)) -> 5 | J30: CHI CUADRADO Y CHI CUADRADO CRITICO
A31: 30 | B31: 25000 | C31: =_xlfn.NUMBERVALUE(MID(B31,2,1)) -> 5 | I31: SUMATORIA DE VALOR OBSERVADO MENOS VALOR ESPERADO ELEVADO AL CUADRADO
A32: 31 | B32: 126600 | C32: =_xlfn.NUMBERVALUE(MID(B32,2,1)) -> 2 | I32: VALOR ESPERADO
A33: 32 | B33: 101600 | C33: =_xlfn.NUMBERVALUE(MID(B33,2,1)) -> 0 | D33: VAMOS A VER LA FRECUENCIA EN QUE SE REPITE CADA NUMERO | J33: VALOR ESPERADO BENFORD = TOTAL DATOS POR % BENFORD
A34: 33 | B34: 25000 | C34: =_xlfn.NUMBERVALUE(MID(B34,2,1)) -> 5 | E34: ACUMULADA | F34: FRECUENCIA | G34: % OBSERVADO | H34: BENFORD UN DIGITO | K34: VALOR OBSERVADO MENOS VALOR ESPERADO ELEVADO AL CUADRADO
A35: 34 | B35: 153300 | C35: =_xlfn.NUMBERVALUE(MID(B35,2,1)) -> 5 | D35: 0 | E35: =FREQUENCY($C$2:$C$9657,D35) -> #VALUE! | F35: =+E35 -> #VALUE! | G35: =+F35/$F$16 -> #VALUE! | H35: 0.11967927 | J35: =+$F$46*H35 -> #VALUE! | K35: =+((F35-J35)^2)/J35 -> #VALUE!
A36: 35 | B36: 153300 | C36: =_xlfn.NUMBERVALUE(MID(B36,2,1)) -> 5 | D36: 1 | E36: =FREQUENCY($C$2:$C$9657,D36) -> #VALUE! | F36: =+E36-E35 -> #VALUE! | G36: =+F36/$F$16 -> #VALUE! | H36: 0.1138901 | J36: =+$F$46*H36 -> #VALUE! | K36: =+((F36-J36)^2)/J36 -> #VALUE!
A37: 36 | B37: 217300 | C37: =_xlfn.NUMBERVALUE(MID(B37,2,1)) -> 1 | D37: 2 | E37: =FREQUENCY($C$2:$C$9657,D37) -> #VALUE! | F37: =+E37-E36 -> #VALUE! | G37: =+F37/$F$16 -> #VALUE! | H37: 0.1088215 | J37: =+$F$46*H37 -> #VALUE! | K37: =+((F37-J37)^2)/J37 -> #VALUE!
A38: 37 | B38: 217300 | C38: =_xlfn.NUMBERVALUE(MID(B38,2,1)) -> 1 | D38: 3 | E38: =FREQUENCY($C$2:$C$9657,D38) -> #VALUE! | F38: =+E38-E37 -> #VALUE! | G38: =+F38/$F$16 -> #VALUE! | H38: 0.10432956 | J38: =+$F$46*H38 -> #VALUE! | K38: =+((F38-J38)^2)/J38 -> #VALUE!
A39: 38 | B39: 152200 | C39: =_xlfn.NUMBERVALUE(MID(B39,2,1)) -> 5 | D39: 4 | E39: =FREQUENCY($C$2:$C$9657,D39) -> #VALUE! | F39: =+E39-E38 -> #VALUE! | G39: =+F39/$F$16 -> #VALUE! | H39: 0.1003082 | J39: =+$F$46*H39 -> #VALUE! | K39: =+((F39-J39)^2)/J39 -> #VALUE!
A40: 39 | B40: 147900 | C40: =_xlfn.NUMBERVALUE(MID(B40,2,1)) -> 4 | D40: 5 | E40: =FREQUENCY($C$2:$C$9657,D40) -> #VALUE! | F40: =+E40-E39 -> #VALUE! | G40: =+F40/$F$16 -> #VALUE! | H40: 0.096677236 | J40: =+$F$46*H40 -> #VALUE! | K40: =+((F40-J40)^2)/J40 -> #VALUE!
...

Sheet PRIMEROS DOS DIGITOS
A1: REGISTRO | B1: VALOR | C1: VAMOS A EXTRAER LOS DOS PRIMEROS DIGITOS | J1: DESVIACION ABSOLUTA MEDIA (MAD) | P1: ESTA MAD LA COMPARAMOS CON LA TABLA PARA EL SEGUNDO DIGITO
A2: 1 | B2: 153800 | C2: =_xlfn.NUMBERVALUE(MID(B2,1,2)) -> 15 | I2: VALOR ABSOLUTO (FRECUENCIA OBSERVADA - FRECUENCIA ESPERADA)
A3: =+A2+1 -> 2 | B3: 9000 | C3: =_xlfn.NUMBERVALUE(MID(B3,1,2)) -> 90 | D3: VAMOS A VER LA FRECUENCIA EN QUE SE REPITE CADA NUMERO | I3: N = 90
A4: =+A3+1 -> 3 | B4: 37800 | C4: =_xlfn.NUMBERVALUE(MID(B4,1,2)) -> 37 | E4: ACUMULADA | F4: FRECUENCIA | G4: % OBSERVADO | H4: BENFORD DOS PRIMEROS DIGITOS | J4: VARIACION | K4: VALOR ABSOLUTO
A5: =+A4+1 -> 4 | B5: 100000 | C5: =_xlfn.NUMBERVALUE(MID(B5,1,2)) -> 10 | D5: 10 | E5: =FREQUENCY($C$2:$C$9657,D5) -> 453 | F5: =+E5 -> 453 | G5: =+F5/$F$96 -> 0.046913836 | H5: 0.041392685 | J5: =+(G5-H5) -> 0.0055211508 | K5: =ABS(J5) -> 0.0055211508
A6: =+A5+1 -> 5 | B6: 25000 | C6: =_xlfn.NUMBERVALUE(MID(B6,1,2)) -> 25 | D6: 11 | E6: =FREQUENCY($C$2:$C$9657,D6) -> 900 | F6: =+E6-F5 -> 447 | G6: =+F6/$F$96 -> 0.046292461 | H6: 0.037788561 | J6: =+(G6-H6) -> 0.0085038998 | K6: =ABS(J6) -> 0.0085038998
A7: =+A6+1 -> 6 | B7: 182900 | C7: =_xlfn.NUMBERVALUE(MID(B7,1,2)) -> 18 | D7: 12 | E7: =FREQUENCY($C$2:$C$9657,D7) -> 1262 | F7: =+E7-E6 -> 362 | G7: =+F7/$F$96 -> 0.037489644 | H7: 0.034762106 | J7: =+(G7-H7) -> 0.0027275375 | K7: =ABS(J7) -> 0.0027275375
A8: =+A7+1 -> 7 | B8: 157900 | C8: =_xlfn.NUMBERVALUE(MID(B8,1,2)) -> 15 | D8: 13 | E8: =FREQUENCY($C$2:$C$9657,D8) -> 1590 | F8: =+E8-E7 -> 328 | G8: =+F8/$F$96 -> 0.033968517 | H8: 0.032184683 | J8: =+(G8-H8) -> 0.0017838336 | K8: =ABS(J8) -> 0.0017838336
A9: =+A8+1 -> 8 | B9: 25000 | C9: =_xlfn.NUMBERVALUE(MID(B9,1,2)) -> 25 | D9: 14 | E9: =FREQUENCY($C$2:$C$9657,D9) -> 1923 | F9: =+E9-E8 -> 333 | G9: =+F9/$F$96 -> 0.03448633 | H9: 0.029963223 | J9: =+(G9-H9) -> 0.0045231064 | K9: =ABS(J9) -> 0.0045231064 | L9: MAD | M9: =+K96/90 -> 0.001845411 | N9: EN ESTE CASO NOS DA 0.001845411 QUE VIENDOLO EN LA TABA ES CONFORMIDAD MARGINALMENTE ACEPTABLE
A10: =+A9+1 -> 9 | B10: 181550 | C10: =_xlfn.NUMBERVALUE(MID(B10,1,2)) -> 18 | D10: 15 | E10: =FREQUENCY($C$2:$C$9657,D10) -> 2280 | F10: =+E10-E9 -> 357 | G10: =+F10/$F$96 -> 0.036971831 | H10: 0.028028724 | J10: =+(G10-H10) -> 0.0089431074 | K10: =ABS(J10) -> 0.0089431074
A11: =+A10+1 -> 10 | B11: 6000 | C11: =_xlfn.NUMBERVALUE(MID(B11,1,2)) -> 60 | D11: 16 | E11: =FREQUENCY($C$2:$C$9657,D11) -> 2559 | F11: =+E11-E10 -> 279 | G11: =+F11/$F$96 -> 0.028893952 | H11: 0.026328939 | J11: =+(G11-H11) -> 0.0025650132 | K11: =ABS(J11) -> 0.0025650132 | Q11: CHI CUADRADO Y CHI CUADRADO CRITICO
A12: =+A11+1 -> 11 | B12: 175550 | C12: =_xlfn.NUMBERVALUE(MID(B12,1,2)) -> 17 | D12: 17 | E12: =FREQUENCY($C$2:$C$9657,D12) -> 2814 | F12: =+E12-E11 -> 255 | G12: =+F12/$F$96 -> 0.026408451 | H12: 0.024823584 | J12: =+(G12-H12) -> 0.001584867 | K12: =ABS(J12) -> 0.001584867 | O12: SUMATORIA DE VALOR OBSERVADO MENOS VALOR ESPERADO ELEVADO AL CUADRADO
A13: =+A12+1 -> 12 | B13: 75500 | C13: =_xlfn.NUMBERVALUE(MID(B13,1,2)) -> 75 | D13: 18 | E13: =FREQUENCY($C$2:$C$9657,D13) -> 3092 | F13: =+E13-E12 -> 278 | G13: =+F13/$F$96 -> 0.028790389 | H13: 0.023481096 | J13: =+(G13-H13) -> 0.0053092935 | K13: =ABS(J13) -> 0.0053092935 | O13: VALOR ESPERADO
A14: =+A13+1 -> 13 | B14: 1000 | C14: =_xlfn.NUMBERVALUE(MID(B14,1,2)) -> 10 | D14: 19 | E14: =FREQUENCY($C$2:$C$9657,D14) -> 3321 | F14: =+E14-E13 -> 229 | G14: =+F14/$F$96 -> 0.023715824 | H14: 0.022276395 | J14: =+(G14-H14) -> 0.0014394296 | K14: =ABS(J14) -> 0.0014394296 | N14: VAMOS A VER LA FRECUENCIA EN QUE SE REPITE CADA NUMERO | T14: VALOR ESPERADO BENFORD = TOTAL DATOS POR % BENFORD
A15: =+A14+1 -> 14 | B15: 74500 | C15: =_xlfn.NUMBERVALUE(MID(B15,1,2)) -> 74 | D15: 20 | E15: =FREQUENCY($C$2:$C$9657,D15) -> 3594 | F15: =+E15-E14 -> 273 | G15: =+F15/$F$96 -> 0.028272577 | H15: 0.021189299 | J15: =+(G15-H15) -> 0.0070832776 | K15: =ABS(J15) -> 0.0070832776 | O15: ACUMULADA | P15: FRECUENCIA | Q15: % OBSERVADO | R15: BENFORD UN DIGITO | U15: VALOR OBSERVADO MENOS VALOR ESPERADO ELEVADO AL CUADRADO
A16: =+A15+1 -> 15 | B16: 184610 | C16: =_xlfn.NUMBERVALUE(MID(B16,1,2)) -> 18 | D16: 21 | E16: =FREQUENCY($C$2:$C$9657,D16) -> 3761 | F16: =+E16-E15 -> 167 | G16: =+F16/$F$96 -> 0.017294946 | H16: 0.020203386 | J16: =+(G16-H16) -> -0.0029084399 | K16: =ABS(J16) -> 0.0029084399 | N16: =+D5 -> 10 | O16: =FREQUENCY($C$2:$C$9657,N16) -> 453 | P16: =+O16 -> 453 | Q16: =+G5 -> 0.046913836 | R16: =+H5 -> 0.041392685 | T16: =+$P$107*R16 -> 399.68777 | U16: =+((P16-T16)^2)/T16 -> 7.111036
A17: =+A16+1 -> 16 | B17: 184610 | C17: =_xlfn.NUMBERVALUE(MID(B17,1,2)) -> 18 | D17: 22 | E17: =FREQUENCY($C$2:$C$9657,D17) -> 3945 | F17: =+E17-E16 -> 184 | G17: =+F17/$F$96 -> 0.01905551 | H17: 0.019305155 | J17: =+(G17-H17) -> -0.00024964567 | K17: =ABS(J17) -> 0.00024964567 | N17: =+D6 -> 11 | O17: =FREQUENCY($C$2:$C$9657,N17) -> 900 | P17: =+O17-O16 -> 447 | Q17: =+G6 -> 0.046292461 | R17: =+H6 -> 0.037788561 | T17: =+$P$107*R17 -> 364.88634 | U17: =+((P17-T17)^2)/T17 -> 18.478775 | V17: ESTE VALOR LO COMPARO CON 112.021986 QUE ES VALOR DEL CHI CUADRADO CRITICO PARA LOS DOS PRIMEROS DIGITOS
A18: =+A17+1 -> 17 | B18: 128000 | C18: =_xlfn.NUMBERVALUE(MID(B18,1,2)) -> 12 | D18: 23 | E18: =FREQUENCY($C$2:$C$9657,D18) -> 4099 | F18: =+E18-E17 -> 154 | G18: =+F18/$F$96 -> 0.015948633 | H18: 0.018483406 | J18: =+(G18-H18) -> -0.0025347727 | K18: =ABS(J18) -> 0.0025347727 | N18: =+D7 -> 12 | O18: =FREQUENCY($C$2:$C$9657,N18) -> 1262 | P18: =+O18-O17 -> 362 | Q18: =+G7 -> 0.037489644 | R18: =+H7 -> 0.034762106 | T18: =+$P$107*R18 -> 335.6629 | U18: =+((P18-T18)^2)/T18 -> 2.0664868 | V18: QUE SALE DE LA TABLA CHI CUADRADO CON UN 95% DE PROBABILIDAD Y ES FIJO
A19: =+A18+1 -> 18 | B19: 128000 | C19: =_xlfn.NUMBERVALUE(MID(B19,1,2)) -> 12 | D19: 24 | E19: =FREQUENCY($C$2:$C$9657,D19) -> 4293 | F19: =+E19-E18 -> 194 | G19: =+F19/$F$96 -> 0.020091135 | H19: 0.017728767 | J19: =+(G19-H19) -> 0.0023623681 | K19: =ABS(J19) -> 0.0023623681 | N19: =+D8 -> 13 | O19: =FREQUENCY($C$2:$C$9657,N19) -> 1590 | P19: =+O19-O18 -> 328 | Q19: =+G8 -> 0.033968517 | R19: =+H8 -> 0.032184683 | T19: =+$P$107*R19 -> 310.7753 | U19: =+((P19-T19)^2)/T19 -> 0.95467753
A20: =+A19+1 -> 19 | B20: 370370 | C20: =_xlfn.NUMBERVALUE(MID(B20,1,2)) -> 37 | D20: 25 | E20: =FREQUENCY($C$2:$C$9657,D20) -> 4459 | F20: =+E20-E19 -> 166 | G20: =+F20/$F$96 -> 0.017191384 | H20: 0.017033339 | J20: =+(G20-H20) -> 0.0001580443 | K20: =ABS(J20) -> 0.0001580443 | N20: =+D9 -> 14 | O20: =FREQUENCY($C$2:$C$9657,N20) -> 1923 | P20: =+O20-O19 -> 333 | Q20: =+G9 -> 0.03448633 | R20: =+H9 -> 0.029963223 | T20: =+$P$107*R20 -> 289.32488 | U20: =+((P20-T20)^2)/T20 -> 6.5929886
A21: =+A20+1 -> 20 | B21: 324485 | C21: =_xlfn.NUMBERVALUE(MID(B21,1,2)) -> 32 | D21: 26 | E21: =FREQUENCY($C$2:$C$9657,D21) -> 4612 | F21: =+E21-E20 -> 153 | G21: =+F21/$F$96 -> 0.01584507 | H21: 0.016390416 | J21: =+(G21-H21) -> -0.00054534577 | K21: =ABS(J21) -> 0.00054534577 | N21: =+D10 -> 15 | O21: =FREQUENCY($C$2:$C$9657,N21) -> 2280 | P21: =+O21-O20 -> 357 | Q21: =+G10 -> 0.036971831 | R21: =+H10 -> 0.028028724 | T21: =+$P$107*R21 -> 270.64536 | U21: =+((P21-T21)^2)/T21 -> 27.553123 | V21: SI EL CHI CUADRADO DA MAYOR QUE ESTE ULTIMO DATO, LOS DATOS DEL MOVIMIENTO SON
A22: =+A21+1 -> 21 | B22: 45885 | C22: =_xlfn.NUMBERVALUE(MID(B22,1,2)) -> 45 | D22: 27 | E22: =FREQUENCY($C$2:$C$9657,D22) -> 4777 | F22: =+E22-E21 -> 165 | G22: =+F22/$F$96 -> 0.017087821 | H22: 0.015794267 | J22: =+(G22-H22) -> 0.0012935539 | K22: =ABS(J22) -> 0.0012935539 | N22: =+D11 -> 16 | O22: =FREQUENCY($C$2:$C$9657,N22) -> 2559 | P22: =+O22-O21 -> 279 | Q22: =+G11 -> 0.028893952 | R22: =+H11 -> 0.026328939 | T22: =+$P$107*R22 -> 254.23223 | U22: =+((P22-T22)^2)/T22 -> 2.4129211 | V22: CONFIABLES
A23: =+A22+1 -> 22 | B23: 352295 | C23: =_xlfn.NUMBERVALUE(MID(B23,1,2)) -> 35 | D23: 28 | E23: =FREQUENCY($C$2:$C$9657,D23) -> 4908 | F23: =+E23-E22 -> 131 | G23: =+F23/$F$96 -> 0.013566694 | H23: 0.015239967 | J23: =+(G23-H23) -> -0.0016732723 | K23: =ABS(J23) -> 0.0016732723 | N23: =+D12 -> 17 | O23: =FREQUENCY($C$2:$C$9657,N23) -> 2814 | P23: =+O23-O22 -> 255 | Q23: =+G12 -> 0.026408451 | R23: =+H12 -> 0.024823584 | T23: =+$P$107*R23 -> 239.69652 | U23: =+((P23-T23)^2)/T23 -> 0.97705365
A24: =+A23+1 -> 23 | B24: 335095 | C24: =_xlfn.NUMBERVALUE(MID(B24,1,2)) -> 33 | D24: 29 | E24: =FREQUENCY($C$2:$C$9657,D24) -> 5073 | F24: =+E24-E23 -> 165 | G24: =+F24/$F$96 -> 0.017087821 | H24: 0.014723257 | J24: =+(G24-H24) -> 0.0023645642 | K24: =ABS(J24) -> 0.0023645642 | N24: =+D13 -> 18 | O24: =FREQUENCY($C$2:$C$9657,N24) -> 3092 | P24: =+O24-O23 -> 278 | Q24: =+G13 -> 0.028790389 | R24: =+H13 -> 0.023481096 | T24: =+$P$107*R24 -> 226.73346 | U24: =+((P24-T24)^2)/T24 -> 11.59184 | V24: ES DECIR | W24: =+U107 -> 439.65133 | X24: MAYOR QUE | Y24: 112.02199 | Z24: RESULTADO | AA24: CONFIABLE
A25: =+A24+1 -> 24 | B25: 1800 | C25: =_xlfn.NUMBERVALUE(MID(B25,1,2)) -> 18 | D25: 30 | E25: =FREQUENCY($C$2:$C$9657,D25) -> 5235 | F25: =+E25-E24 -> 162 | G25: =+F25/$F$96 -> 0.016777133 | H25: 0.014240439 | J25: =+(G25-H25) -> 0.0025366943 | K25: =ABS(J25) -> 0.0025366943 | N25: =+D14 -> 19 | O25: =FREQUENCY($C$2:$C$9657,N25) -> 3321 | P25: =+O25-O24 -> 229 | Q25: =+G14 -> 0.023715824 | R25: =+H14 -> 0.022276395 | T25: =+$P$107*R25 -> 215.10087 | U25: =+((P25-T25)^2)/T25 -> 0.89811767
A26: =+A25+1 -> 25 | B26: 7000 | C26: =_xlfn.NUMBERVALUE(MID(B26,1,2)) -> 70 | D26: 31 | E26: =FREQUENCY($C$2:$C$9657,D26) -> 5364 | F26: =+E26-E25 -> 129 | G26: =+F26/$F$96 -> 0.013359569 | H26: 0.013788284 | J26: =+(G26-H26) -> -0.00042871531 | K26: =ABS(J26) -> 0.00042871531 | N26: =+D15 -> 20 | O26: =FREQUENCY($C$2:$C$9657,N26) -> 3594 | P26: =+O26-O25 -> 273 | Q26: =+G15 -> 0.028272577 | R26: =+H15 -> 0.021189299 | T26: =+$P$107*R26 -> 204.60387 | U26: =+((P26-T26)^2)/T26 -> 22.863841
A27: =+A26+1 -> 26 | B27: 8375 | C27: =_xlfn.NUMBERVALUE(MID(B27,1,2)) -> 83 | D27: 32 | E27: =FREQUENCY($C$2:$C$9657,D27) -> 5495 | F27: =+E27-E26 -> 131 | G27: =+F27/$F$96 -> 0.013566694 | H27: 0.013363962 | J27: =+(G27-H27) -> 0.00020273273 | K27: =ABS(J27) -> 0.00020273273 | N27: =+D16 -> 21 | O27: =FREQUENCY($C$2:$C$9657,N27) -> 3761 | P27: =+O27-O26 -> 167 | Q27: =+G16 -> 0.017294946 | R27: =+H16 -> 0.020203386 | T27: =+$P$107*R27 -> 195.0839 | U27: =+((P27-T27)^2)/T27 -> 4.0429027
A28: =+A27+1 -> 27 | B28: 25 | C28: =_xlfn.NUMBERVALUE(MID(B28,1,2)) -> 25 | D28: 33 | E28: =FREQUENCY($C$2:$C$9657,D28) -> 5608 | F28: =+E28-E27 -> 113 | G28: =+F28/$F$96 -> 0.011702568 | H28: 0.012964977 | J28: =+(G28-H28) -> -0.0012624088 | K28: =ABS(J28) -> 0.0012624088 | N28: =+D17 -> 22 | O28: =FREQUENCY($C$2:$C$9657,N28) -> 3945 | P28: =+O28-O27 -> 184 | Q28: =+G17 -> 0.01905551 | R28: =+H17 -> 0.019305155 | T28: =+$P$107*R28 -> 186.41058 | U28: =+((P28-T28)^2)/T28 -> 0.031172528
A29: =+A28+1 -> 28 | B29: 182350 | C29: =_xlfn.NUMBERVALUE(MID(B29,1,2)) -> 18 | D29: 34 | E29: =FREQUENCY($C$2:$C$9657,D29) -> 5713 | F29: =+E29-E28 -> 105 | G29: =+F29/$F$96 -> 0.010874068 | H29: 0.012589127 | J29: =+(G29-H29) -> -0.0017150594 | K29: =ABS(J29) -> 0.0017150594 | N29: =+D18 -> 23 | O29: =FREQUENCY($C$2:$C$9657,N29) -> 4099 | P29: =+O29-O28 -> 154 | Q29: =+G18 -> 0.015948633 | R29: =+H18 -> 0.018483406 | T29: =+$P$107*R29 -> 178.47577 | U29: =+((P29-T29)^2)/T29 -> 3.3565515
A30: =+A29+1 -> 29 | B30: 157350 | C30: =_xlfn.NUMBERVALUE(MID(B30,1,2)) -> 15 | D30: 35 | E30: =FREQUENCY($C$2:$C$9657,D30) -> 5843 | F30: =+E30-E29 -> 130 | G30: =+F30/$F$96 -> 0.013463132 | H30: 0.012234456 | J30: =+(G30-H30) -> 0.0012286753 | K30: =ABS(J30) -> 0.0012286753 | N30: =+D19 -> 24 | O30: =FREQUENCY($C$2:$C$9657,N30) -> 4293 | P30: =+O30-O29 -> 194 | Q30: =+G19 -> 0.020091135 | R30: =+H19 -> 0.017728767 | T30: =+$P$107*R30 -> 171.18897 | U30: =+((P30-T30)^2)/T30 -> 3.039582
A31: =+A30+1 -> 30 | B31: 25000 | C31: =_xlfn.NUMBERVALUE(MID(B31,1,2)) -> 25 | D31: 36 | E31: =FREQUENCY($C$2:$C$9657,D31) -> 5958 | F31: =+E31-E30 -> 115 | G31: =+F31/$F$96 -> 0.011909693 | H31: 0.011899223 | J31: =+(G31-H31) -> 1.0470155e-05 | K31: =ABS(J31) -> 1.0470155e-05 | N31: =+D20 -> 25 | O31: =FREQUENCY($C$2:$C$9657,N31) -> 4459 | P31: =+O31-O30 -> 166 | Q31: =+G20 -> 0.017191384 | R31: =+H20 -> 0.017033339 | T31: =+$P$107*R31 -> 164.47392 | U31: =+((P31-T31)^2)/T31 -> 0.014159735
A32: =+A31+1 -> 31 | B32: 126600 | C32: =_xlfn.NUMBERVALUE(MID(B32,1,2)) -> 12 | D32: 37 | E32: =FREQUENCY($C$2:$C$9657,D32) -> 6042 | F32: =+E32-E31 -> 84 | G32: =+F32/$F$96 -> 0.0086992543 | H32: 0.011581873 | J32: =+(G32-H32) -> -0.0028826182 | K32: =ABS(J32) -> 0.0028826182 | N32: =+D21 -> 26 | O32: =FREQUENCY($C$2:$C$9657,N32) -> 4612 | P32: =+O32-O31 -> 153 | Q32: =+G21 -> 0.01584507 | R32: =+H21 -> 0.016390416 | T32: =+$P$107*R32 -> 158.26586 | U32: =+((P32-T32)^2)/T32 -> 0.17520688
A33: =+A32+1 -> 32 | B33: 101600 | C33: =_xlfn.NUMBERVALUE(MID(B33,1,2)) -> 10 | D33: 38 | E33: =FREQUENCY($C$2:$C$9657,D33) -> 6148 | F33: =+E33-E32 -> 106 | G33: =+F33/$F$96 -> 0.01097763 | H33: 0.01128101 | J33: =+(G33-H33) -> -0.00030337992 | K33: =ABS(J33) -> 0.00030337992 | N33: =+D22 -> 27 | O33: =FREQUENCY($C$2:$C$9657,N33) -> 4777 | P33: =+O33-O32 -> 165 | Q33: =+G22 -> 0.017087821 | R33: =+H22 -> 0.015794267 | T33: =+$P$107*R33 -> 152.50944 | U33: =+((P33-T33)^2)/T33 -> 1.0229792
A34: =+A33+1 -> 33 | B34: 25000 | C34: =_xlfn.NUMBERVALUE(MID(B34,1,2)) -> 25 | D34: 39 | E34: =FREQUENCY($C$2:$C$9657,D34) -> 6242 | F34: =+E34-E33 -> 94 | G34: =+F34/$F$96 -> 0.0097348799 | H34: 0.010995384 | J34: =+(G34-H34) -> -0.0012605044 | K34: =ABS(J34) -> 0.0012605044 | N34: =+D23 -> 28 | O34: =FREQUENCY($C$2:$C$9657,N34) -> 4908 | P34: =+O34-O33 -> 131 | Q34: =+G23 -> 0.013566694 | R34: =+H23 -> 0.015239967 | T34: =+$P$107*R34 -> 147.15712 | U34: =+((P34-T34)^2)/T34 -> 1.7739708
A35: =+A34+1 -> 34 | B35: 153300 | C35: =_xlfn.NUMBERVALUE(MID(B35,1,2)) -> 15 | D35: 40 | E35: =FREQUENCY($C$2:$C$9657,D35) -> 6355 | F35: =+E35-E34 -> 113 | G35: =+F35/$F$96 -> 0.011702568 | H35: 0.010723865 | J35: =+(G35-H35) -> 0.00097870296 | K35: =ABS(J35) -> 0.00097870296 | N35: =+D24 -> 29 | O35: =FREQUENCY($C$2:$C$9657,N35) -> 5073 | P35: =+O35-O34 -> 165 | Q35: =+G24 -> 0.017087821 | R35: =+H24 -> 0.014723257 | T35: =+$P$107*R35 -> 142.16777 | U35: =+((P35-T35)^2)/T35 -> 3.6668707
A36: =+A35+1 -> 35 | B36: 153300 | C36: =_xlfn.NUMBERVALUE(MID(B36,1,2)) -> 15 | D36: 41 | E36: =FREQUENCY($C$2:$C$9657,D36) -> 6420 | F36: =+E36-E35 -> 65 | G36: =+F36/$F$96 -> 0.0067315659 | H36: 0.010465434 | J36: =+(G36-H36) -> -0.0037338678 | K36: =ABS(J36) -> 0.0037338678 | N36: =+D25 -> 30 | O36: =FREQUENCY($C$2:$C$9657,N36) -> 5235 | P36: =+O36-O35 -> 162 | Q36: =+G25 -> 0.016777133 | R36: =+H25 -> 0.014240439 | T36: =+$P$107*R36 -> 137.50568 | U36: =+((P36-T36)^2)/T36 -> 4.3632504
... A94: =+A93+1 -> 93 | B94: 59974 | C94: =_xlfn.NUMBERVALUE(MID(B94,1,2)) -> 59 | D94: 99 | E94: =FREQUENCY($C$2:$C$9657,D94) -> 9656 | F94: =+E94-E93 -> 22 | G94: =+F94/$F$96 -> 0.0022783761 | H94: 0.0043648054 | J94: =+(G94-H94) -> -0.0020864293 | K94: =ABS(J94) -> 0.0020864293 | N94: =+D83 -> 88 | O94: =FREQUENCY($C$2:$C$9657,N94) -> 9210 | P94: =+O94-O93 -> 49 | Q94: =+G83 -> 0.005074565 | R94: =+H83 -> 0.0049073345 | T94: =+$P$107*R94 -> 47.385222 | U94: =+((P94-T94)^2)/T94 -> 0.055027881
A95: =+A94+1 -> 94 | B95: 299700 | C95: =_xlfn.NUMBERVALUE(MID(B95,1,2)) -> 29 | N95: =+D84 -> 89 | O95: =FREQUENCY($C$2:$C$9657,N95) -> 9259 | P95: =+O95-O94 -> 49 | Q95: =+G84 -> 0.005074565 | R95: =+H84 -> 0.0048525028 | T95: =+$P$107*R95 -> 46.855767 | U95: =+((P95-T95)^2)/T95 -> 0.09812528
A96: =+A95+1 -> 95 | B96: 54875 | C96: =_xlfn.NUMBERVALUE(MID(B96,1,2)) -> 54 | E96: TOTAL | F96: =SUM(F5:F95) -> 9656 | G96: =SUM(G5:G94) -> 1 | H96: =SUM(H5:H94) -> 1 | J96: =SUM(J5:J95) -> 0 | K96: =SUM(K5:K95) -> 0.16608699 | N96: =+D85 -> 90 | O96: =FREQUENCY($C$2:$C$9657,N96) -> 9300 | P96: =+O96-O95 -> 41 | Q96: =+G85 -> 0.0042460646 | R96: =+H85 -> 0.0047988829 | T96: =+$P$107*R96 -> 46.338013 | U96: =+((P96-T96)^2)/T96 -> 0.61492459
A97: =+A96+1 -> 96 | B97: 12000 | C97: =_xlfn.NUMBERVALUE(MID(B97,1,2)) -> 12 | N97: =+D86 -> 91 | O97: =FREQUENCY($C$2:$C$9657,N97) -> 9327 | P97: =+O97-O96 -> 27 | Q97: =+G86 -> 0.0027961889 | R97: =+H86 -> 0.004746435 | T97: =+$P$107*R97 -> 45.831577 | U97: =+((P97-T97)^2)/T97 -> 7.7376408
...

Sheet GRAFICA  PRIMER DIGITO
A2: NUMERO | B2: OBSERVADO | C2: BENFORD
A3: 1 | B3: =+'PRIMER DIGITO'!G5 -> 0.34351698 | C3: =+'PRIMER DIGITO'!H5 -> 0.30103
A4: 2 | B4: =+'PRIMER DIGITO'!G6 -> 0.18144159 | C4: =+'PRIMER DIGITO'!H6 -> 0.17609126
A5: 3 | B5: =+'PRIMER DIGITO'!G7 -> 0.12127175 | C5: =+'PRIMER DIGITO'!H7 -> 0.12493874
A6: 4 | B6: =+'PRIMER DIGITO'!G8 -> 0.085024855 | C6: =+'PRIMER DIGITO'!H8 -> 0.096910013
A7: 5 | B7: =+'PRIMER DIGITO'!G9 -> 0.0754971 | C7: =+'PRIMER DIGITO'!H9 -> 0.079181246
A8: 6 | B8: =+'PRIMER DIGITO'!G10 -> 0.053852527 | C8: =+'PRIMER DIGITO'!H10 -> 0.06694679
A9: 7 | B9: =+'PRIMER DIGITO'!G11 -> 0.051574151 | C9: =+'PRIMER DIGITO'!H11 -> 0.057991947
A10: 8 | B10: =+'PRIMER DIGITO'!G12 -> 0.046706711 | C10: =+'PRIMER DIGITO'!H12 -> 0.051152522
A11: 9 | B11: =+'PRIMER DIGITO'!G13 -> 0.041114333 | C11: =+'PRIMER DIGITO'!H13 -> 0.045757491

Sheet GRAFICA SEGUNDO DIGITO
A2: NUMERO | B2: OBSERVADO | C2: BENFORD
A3: 0 | B3: =+'SEGUNDO DIGITO'!G35 -> #VALUE! | C3: =+'SEGUNDO DIGITO'!H35 -> 0.11967927
A4: 1 | B4: =+'SEGUNDO DIGITO'!G36 -> #VALUE! | C4: =+'SEGUNDO DIGITO'!H36 -> 0.1138901
A5: 2 | B5: =+'SEGUNDO DIGITO'!G37 -> #VALUE! | C5: =+'SEGUNDO DIGITO'!H37 -> 0.1088215
A6: 3 | B6: =+'SEGUNDO DIGITO'!G38 -> #VALUE! | C6: =+'SEGUNDO DIGITO'!H38 -> 0.10432956
A7: 4 | B7: =+'SEGUNDO DIGITO'!G39 -> #VALUE! | C7: =+'SEGUNDO DIGITO'!H39 -> 0.1003082
A8: 5 | B8: =+'SEGUNDO DIGITO'!G40 -> #VALUE! | C8: =+'SEGUNDO DIGITO'!H40 -> 0.096677236
A9: 6 | B9: =+'SEGUNDO DIGITO'!G41 -> #VALUE! | C9: =+'SEGUNDO DIGITO'!H41 -> 0.093374736
A10: 7 | B10: =+'SEGUNDO DIGITO'!G42 -> #VALUE! | C10: =+'SEGUNDO DIGITO'!H42 -> 0.090351989
A11: 8 | B11: =+'SEGUNDO DIGITO'!G43 -> #VALUE! | C11: =+'SEGUNDO DIGITO'!H43 -> 0.087570054
A12: 9 | B12: =+'SEGUNDO DIGITO'!G44 -> #VALUE! | C12: =+'SEGUNDO DIGITO'!H44 -> 0.084997352

Sheet GRAFICA DOS PRIMEROS
A2: NUMERO | B2: OBSERVADO | C2: BENFORD
A3: 10 | B3: =+'PRIMEROS DOS DIGITOS'!G5 -> 0.046913836 | C3: =+'PRIMEROS DOS DIGITOS'!H5 -> 0.041392685
A4: 11 | B4: =+'PRIMEROS DOS DIGITOS'!G6 -> 0.046292461 | C4: =+'PRIMEROS DOS DIGITOS'!H6 -> 0.037788561
A5: 12 | B5: =+'PRIMEROS DOS DIGITOS'!G7 -> 0.037489644 | C5: =+'PRIMEROS DOS DIGITOS'!H7 -> 0.034762106
A6: 13 | B6: =+'PRIMEROS DOS DIGITOS'!G8 -> 0.033968517 | C6: =+'PRIMEROS DOS DIGITOS'!H8 -> 0.032184683
A7: 14 | B7: =+'PRIMEROS DOS DIGITOS'!G9 -> 0.03448633 | C7: =+'PRIMEROS DOS DIGITOS'!H9 -> 0.029963223
A8: 15 | B8: =+'PRIMEROS DOS DIGITOS'!G10 -> 0.036971831 | C8: =+'PRIMEROS DOS DIGITOS'!H10 -> 0.028028724
A9: 16 | B9: =+'PRIMEROS DOS DIGITOS'!G11 -> 0.028893952 | C9: =+'PRIMEROS DOS DIGITOS'!H11 -> 0.026328939
A10: 17 | B10: =+'PRIMEROS DOS DIGITOS'!G12 -> 0.026408451 | C10: =+'PRIMEROS DOS DIGITOS'!H12 -> 0.024823584
A11: 18 | B11: =+'PRIMEROS DOS DIGITOS'!G13 -> 0.028790389 | C11: =+'PRIMEROS DOS DIGITOS'!H13 -> 0.023481096
A12: 19 | B12: =+'PRIMEROS DOS DIGITOS'!G14 -> 0.023715824 | C12: =+'PRIMEROS DOS DIGITOS'!H14 -> 0.022276395
A13: 20 | B13: =+'PRIMEROS DOS DIGITOS'!G15 -> 0.028272577 | C13: =+'PRIMEROS DOS DIGITOS'!H15 -> 0.021189299
A14: 21 | B14: =+'PRIMEROS DOS DIGITOS'!G16 -> 0.017294946 | C14: =+'PRIMEROS DOS DIGITOS'!H16 -> 0.020203386
... A92: 99 | B92: =+'PRIMEROS DOS DIGITOS'!G94 -> 0.0022783761 | C92: =+'PRIMEROS DOS DIGITOS'!H94 -> 0.0043648054
